Workbook

Sheet PREMISAS
B1: PREMISAS DEL PLAN DE OPERACIONES — M4
B3: TABLA 1 — PARÁMETROS DE TIEMPO
B4: Parámetro | C4: Valor
B5: Días capacitación presencial | C5: 8
B6: Horas por día | C6: 5
B7: Días preparación técnico lead | C7: 2
B8: Días viaje ida+vuelta | C8: 2
B9: HH/día facturables | C9: 8
B10: Noches hospedaje | C10: 9
B11: Total días facturables LEAD (cap+prep+viaje) | C11: =C5+C7+C8
B12: Total días facturables APOYO (cap+viaje) | C12: =C5+C8
B14: TABLA 2 — TARIFAS TÉCNICOS (S/. por hora)
B15: Especialidad | C15: Tarifa Lead | D15: Tarifa Apoyo
B16: Cocina y Repostería | C16: 25 | D16: 18
B17: Computación e Informática | C17: 22 | D17: 15
B18: Construcciones Metálicas | C18: 32 | D18: 23
B19: Ebanistería | C19: 28 | D19: 20
B20: Electricidad | C20: 28 | D20: 20
B21: Electrónica | C21: 32 | D21: 23
B22: Industria Alimentaria | C22: 22 | D22: 15
B23: Industria del Vestido | C23: 22 | D23: 15
B24: Mecánica Automotriz | C24: 32 | D24: 23
B26: TABLA 3 — VIÁTICOS Y TRANSPORTE DIARIO (por persona)
B27: Grupo | C27: Descripción | D27: Viático/día | E27: Transp.interno/día | F27: Noche hospedaje
B28: A | C28: Lima Metropolitana | D28: 60 | E28: 40 | F28: 0
B29: B | C29: Lima Provincia | D29: 120 | E29: 20 | F29: 120
B30: C | C30: Región lejana | D30: 160 | E30: 25 | F30: 100
B32: TABLA 4 — TRASLADO POR IE (por persona ida+vuelta)
B33: IE Código | C33: IE Nombre | D33: Ruta | E33: Medio | F33: Costo S/.
B34: IE1 | C34: 16449 Eloy Soberón Flores | D34: Lima–Jaén | E34: Vuelo | F34: 900
B35: IE2 | C35: 2026 Simón Bolívar | D35: Lima–Comas | E35: Propio | F35: 0
B36: IE3 | C36: 6049 Ricardo Palma | D36: Lima–Surquillo | E36: Propio | F36: 0
B37: IE4 | C37: Francisco Irazola | D37: Lima–Satipo | E37: Bus/Van | F37: 180
B38: IE5 | C38: Guillermo E. Billinghurst | D38: Lima–Barranca | E38: Bus | F38: 60
B39: IE6 | C39: José Granda | D39: Lima–SMP | E39: Propio | F39: 0
B40: IE7 | C40: Manuel A. Mesones Muro | D40: Lima–Tarapoto+Bus | E40: Vuelo+Bus | F40: 750
B42: TABLA 5 — CONSUMIBLES POR ESPECIALIDAD (por taller)
B43: Especialidad | C43: Consumibles S/.
B44: Cocina y Repostería | C44: 800
B45: Computación e Informática | C45: 200
...

Sheet DETALLE M4
A1: PLAN DE OPERACIONES M4 — DETALLE DE TALLERES
A2: IDENTIFICACIÓN | I2: TÉCNICOS | M2: COSTO LABORAL | R2: VIÁTICOS | U2: TRANSPORTE INTERNO | W2: TRASLADO | Y2: HOSPEDAJE | AB2: MATERIALES | AD2: TOTAL
A3: N° | B3: Código | C3: IE Nombre | D3: IE Cód | E3: Ubicación | F3: Grupo | G3: Especialidad | H3: Apoyo Téc. | I3: Personas | J3: Días Lead | K3: Días Apoyo | L3: HH/día | M3: Tarifa Lead | N3: Tarifa Apoyo | O3: Costo Lead | P3: Costo Apoyo | Q3: SUB LABORAL | R3: Viático /día | S3: Días Viático | T3: COSTO VIÁTICOS | U3: Transp /día | V3: COSTO TRANSP | W3: Traslado /pers | X3: COSTO TRASLADO | Y3: Noche Hosp | Z3: Noches | AA3: COSTO HOSPEDAJE | AB3: Consumibles | AC3: Mat. Didáct. | AD3: TOTAL
A4: 1 | B4: T-COCINA-01 | C4: 16449 Eloy Soberón Flores | D4: IE1 | E4: Cajamarca – San Ignacio | F4: C | G4: Cocina y Repostería | H4: NO | I4: =IF(H4="SI",2,1) | J4: =PREMISAS!C11 | K4: =PREMISAS!C12 | L4: =PREMISAS!C9 | M4: =VLOOKUP(G4,PREMISAS!$B$16:$D$24,2,0) | N4: =VLOOKUP(G4,PREMISAS!$B$16:$D$24,3,0) | O4: =J4*L4*M4 | P4: =IF(H4="SI",K4*L4*N4,0) | Q4: =O4+P4 | R4: =VLOOKUP(F4,PREMISAS!$B$28:$F$30,3,0) | S4: =PREMISAS!C5+PREMISAS!C8 | T4: =R4*S4*I4 | U4: =VLOOKUP(F4,PREMISAS!$B$28:$F$30,4,0) | V4: =U4*PREMISAS!C5*I4 | W4: =VLOOKUP(D4,PREMISAS!$B$34:$F$40,5,0) | X4: =W4*I4 | Y4: =VLOOKUP(F4,PREMISAS!$B$28:$F$30,5,0) | Z4: =PREMISAS!C10 | AA4: =Y4*Z4*I4 | AB4: =VLOOKUP(G4,PREMISAS!$B$44:$C$52,2,0) | AC4: =PREMISAS!C56 | AD4: =Q4+T4+V4+X4+AA4+AB4+AC4+IF(F4="C",I4*PREMISAS!C57,0)
A5: 2 | B5: T-COMP-02 | C5: 2026 Simón Bolívar | D5: IE2 | E5: Lima Metropolitana – Comas | F5: A | G5: Computación e Informática | H5: NO | I5: =IF(H5="SI",2,1) | J5: =PREMISAS!C11 | K5: =PREMISAS!C12 | L5: =PREMISAS!C9 | M5: =VLOOKUP(G5,PREMISAS!$B$16:$D$24,2,0) | N5: =VLOOKUP(G5,PREMISAS!$B$16:$D$24,3,0) | O5: =J5*L5*M5 | P5: =IF(H5="SI",K5*L5*N5,0) | Q5: =O5+P5 | R5: =VLOOKUP(F5,PREMISAS!$B$28:$F$30,3,0) | S5: =PREMISAS!C5+PREMISAS!C8 | T5: =R5*S5*I5 | U5: =VLOOKUP(F5,PREMISAS!$B$28:$F$30,4,0) | V5: =U5*PREMISAS!C5*I5 | W5: =VLOOKUP(D5,PREMISAS!$B$34:$F$40,5,0) | X5: =W5*I5 | Y5: =VLOOKUP(F5,PREMISAS!$B$28:$F$30,5,0) | Z5: =PREMISAS!C10 | AA5: =Y5*Z5*I5 | AB5: =VLOOKUP(G5,PREMISAS!$B$44:$C$52,2,0) | AC5: =PREMISAS!C56 | AD5: =Q5+T5+V5+X5+AA5+AB5+AC5+IF(F5="C",I5*PREMISAS!C57,0)
A6: 3 | B6: T-ELEC-02 | C6: 2026 Simón Bolívar | D6: IE2 | E6: Lima Metropolitana – Comas | F6: A | G6: Electricidad | H6: SI | I6: =IF(H6="SI",2,1) | J6: =PREMISAS!C11 | K6: =PREMISAS!C12 | L6: =PREMISAS!C9 | M6: =VLOOKUP(G6,PREMISAS!$B$16:$D$24,2,0) | N6: =VLOOKUP(G6,PREMISAS!$B$16:$D$24,3,0) | O6: =J6*L6*M6 | P6: =IF(H6="SI",K6*L6*N6,0) | Q6: =O6+P6 | R6: =VLOOKUP(F6,PREMISAS!$B$28:$F$30,3,0) | S6: =PREMISAS!C5+PREMISAS!C8 | T6: =R6*S6*I6 | U6: =VLOOKUP(F6,PREMISAS!$B$28:$F$30,4,0) | V6: =U6*PREMISAS!C5*I6 | W6: =VLOOKUP(D6,PREMISAS!$B$34:$F$40,5,0) | X6: =W6*I6 | Y6: =VLOOKUP(F6,PREMISAS!$B$28:$F$30,5,0) | Z6: =PREMISAS!C10 | AA6: =Y6*Z6*I6 | AB6: =VLOOKUP(G6,PREMISAS!$B$44:$C$52,2,0) | AC6: =PREMISAS!C56 | AD6: =Q6+T6+V6+X6+AA6+AB6+AC6+IF(F6="C",I6*PREMISAS!C57,0)
A7: 4 | B7: T-INDUS.A-02 | C7: 2026 Simón Bolívar | D7: IE2 | E7: Lima Metropolitana – Comas | F7: A | G7: Industria Alimentaria | H7: NO | I7: =IF(H7="SI",2,1) | J7: =PREMISAS!C11 | K7: =PREMISAS!C12 | L7: =PREMISAS!C9 | M7: =VLOOKUP(G7,PREMISAS!$B$16:$D$24,2,0) | N7: =VLOOKUP(G7,PREMISAS!$B$16:$D$24,3,0) | O7: =J7*L7*M7 | P7: =IF(H7="SI",K7*L7*N7,0) | Q7: =O7+P7 | R7: =VLOOKUP(F7,PREMISAS!$B$28:$F$30,3,0) | S7: =PREMISAS!C5+PREMISAS!C8 | T7: =R7*S7*I7 | U7: =VLOOKUP(F7,PREMISAS!$B$28:$F$30,4,0) | V7: =U7*PREMISAS!C5*I7 | W7: =VLOOKUP(D7,PREMISAS!$B$34:$F$40,5,0) | X7: =W7*I7 | Y7: =VLOOKUP(F7,PREMISAS!$B$28:$F$30,5,0) | Z7: =PREMISAS!C10 | AA7: =Y7*Z7*I7 | AB7: =VLOOKUP(G7,PREMISAS!$B$44:$C$52,2,0) | AC7: =PREMISAS!C56 | AD7: =Q7+T7+V7+X7+AA7+AB7+AC7+IF(F7="C",I7*PREMISAS!C57,0)
A8: 5 | B8: T-INDUS.V-02 | C8: 2026 Simón Bolívar | D8: IE2 | E8: Lima Metropolitana – Comas | F8: A | G8: Industria del Vestido | H8: NO | I8: =IF(H8="SI",2,1) | J8: =PREMISAS!C11 | K8: =PREMISAS!C12 | L8: =PREMISAS!C9 | M8: =VLOOKUP(G8,PREMISAS!$B$16:$D$24,2,0) | N8: =VLOOKUP(G8,PREMISAS!$B$16:$D$24,3,0) | O8: =J8*L8*M8 | P8: =IF(H8="SI",K8*L8*N8,0) | Q8: =O8+P8 | R8: =VLOOKUP(F8,PREMISAS!$B$28:$F$30,3,0) | S8: =PREMISAS!C5+PREMISAS!C8 | T8: =R8*S8*I8 | U8: =VLOOKUP(F8,PREMISAS!$B$28:$F$30,4,0) | V8: =U8*PREMISAS!C5*I8 | W8: =VLOOKUP(D8,PREMISAS!$B$34:$F$40,5,0) | X8: =W8*I8 | Y8: =VLOOKUP(F8,PREMISAS!$B$28:$F$30,5,0) | Z8: =PREMISAS!C10 | AA8: =Y8*Z8*I8 | AB8: =VLOOKUP(G8,PREMISAS!$B$44:$C$52,2,0) | AC8: =PREMISAS!C56 | AD8: =Q8+T8+V8+X8+AA8+AB8+AC8+IF(F8="C",I8*PREMISAS!C57,0)
A9: 6 | B9: T-COMP-03 | C9: 6049 Ricardo Palma | D9: IE3 | E9: Lima Metropolitana – Surquillo | F9: A | G9: Computación e Informática | H9: NO | I9: =IF(H9="SI",2,1) | J9: =PREMISAS!C11 | K9: =PREMISAS!C12 | L9: =PREMISAS!C9 | M9: =VLOOKUP(G9,PREMISAS!$B$16:$D$24,2,0) | N9: =VLOOKUP(G9,PREMISAS!$B$16:$D$24,3,0) | O9: =J9*L9*M9 | P9: =IF(H9="SI",K9*L9*N9,0) | Q9: =O9+P9 | R9: =VLOOKUP(F9,PREMISAS!$B$28:$F$30,3,0) | S9: =PREMISAS!C5+PREMISAS!C8 | T9: =R9*S9*I9 | U9: =VLOOKUP(F9,PREMISAS!$B$28:$F$30,4,0) | V9: =U9*PREMISAS!C5*I9 | W9: =VLOOKUP(D9,PREMISAS!$B$34:$F$40,5,0) | X9: =W9*I9 | Y9: =VLOOKUP(F9,PREMISAS!$B$28:$F$30,5,0) | Z9: =PREMISAS!C10 | AA9: =Y9*Z9*I9 | AB9: =VLOOKUP(G9,PREMISAS!$B$44:$C$52,2,0) | AC9: =PREMISAS!C56 | AD9: =Q9+T9+V9+X9+AA9+AB9+AC9+IF(F9="C",I9*PREMISAS!C57,0)
A10: 7 | B10: T-ELECTRO-03 | C10: 6049 Ricardo Palma | D10: IE3 | E10: Lima Metropolitana – Surquillo | F10: A | G10: Electrónica | H10: SI | I10: =IF(H10="SI",2,1) | J10: =PREMISAS!C11 | K10: =PREMISAS!C12 | L10: =PREMISAS!C9 | M10: =VLOOKUP(G10,PREMISAS!$B$16:$D$24,2,0) | N10: =VLOOKUP(G10,PREMISAS!$B$16:$D$24,3,0) | O10: =J10*L10*M10 | P10: =IF(H10="SI",K10*L10*N10,0) | Q10: =O10+P10 | R10: =VLOOKUP(F10,PREMISAS!$B$28:$F$30,3,0) | S10: =PREMISAS!C5+PREMISAS!C8 | T10: =R10*S10*I10 | U10: =VLOOKUP(F10,PREMISAS!$B$28:$F$30,4,0) | V10: =U10*PREMISAS!C5*I10 | W10: =VLOOKUP(D10,PREMISAS!$B$34:$F$40,5,0) | X10: =W10*I10 | Y10: =VLOOKUP(F10,PREMISAS!$B$28:$F$30,5,0) | Z10: =PREMISAS!C10 | AA10: =Y10*Z10*I10 | AB10: =VLOOKUP(G10,PREMISAS!$B$44:$C$52,2,0) | AC10: =PREMISAS!C56 | AD10: =Q10+T10+V10+X10+AA10+AB10+AC10+IF(F10="C",I10*PREMISAS!C57,0)
A11: 8 | B11: T-ELEC-03 | C11: 6049 Ricardo Palma | D11: IE3 | E11: Lima Metropolitana – Surquillo | F11: A | G11: Electricidad | H11: SI | I11: =IF(H11="SI",2,1) | J11: =PREMISAS!C11 | K11: =PREMISAS!C12 | L11: =PREMISAS!C9 | M11: =VLOOKUP(G11,PREMISAS!$B$16:$D$24,2,0) | N11: =VLOOKUP(G11,PREMISAS!$B$16:$D$24,3,0) | O11: =J11*L11*M11 | P11: =IF(H11="SI",K11*L11*N11,0) | Q11: =O11+P11 | R11: =VLOOKUP(F11,PREMISAS!$B$28:$F$30,3,0) | S11: =PREMISAS!C5+PREMISAS!C8 | T11: =R11*S11*I11 | U11: =VLOOKUP(F11,PREMISAS!$B$28:$F$30,4,0) | V11: =U11*PREMISAS!C5*I11 | W11: =VLOOKUP(D11,PREMISAS!$B$34:$F$40,5,0) | X11: =W11*I11 | Y11: =VLOOKUP(F11,PREMISAS!$B$28:$F$30,5,0) | Z11: =PREMISAS!C10 | AA11: =Y11*Z11*I11 | AB11: =VLOOKUP(G11,PREMISAS!$B$44:$C$52,2,0) | AC11: =PREMISAS!C56 | AD11: =Q11+T11+V11+X11+AA11+AB11+AC11+IF(F11="C",I11*PREMISAS!C57,0)
A12: 9 | B12: T-INDUS.A-04 | C12: Francisco Irazola | D12: IE4 | E12: Junín – Satipo | F12: C | G12: Industria Alimentaria | H12: NO | I12: =IF(H12="SI",2,1) | J12: =PREMISAS!C11 | K12: =PREMISAS!C12 | L12: =PREMISAS!C9 | M12: =VLOOKUP(G12,PREMISAS!$B$16:$D$24,2,0) | N12: =VLOOKUP(G12,PREMISAS!$B$16:$D$24,3,0) | O12: =J12*L12*M12 | P12: =IF(H12="SI",K12*L12*N12,0) | Q12: =O12+P12 | R12: =VLOOKUP(F12,PREMISAS!$B$28:$F$30,3,0) | S12: =PREMISAS!C5+PREMISAS!C8 | T12: =R12*S12*I12 | U12: =VLOOKUP(F12,PREMISAS!$B$28:$F$30,4,0) | V12: =U12*PREMISAS!C5*I12 | W12: =VLOOKUP(D12,PREMISAS!$B$34:$F$40,5,0) | X12: =W12*I12 | Y12: =VLOOKUP(F12,PREMISAS!$B$28:$F$30,5,0) | Z12: =PREMISAS!C10 | AA12: =Y12*Z12*I12 | AB12: =VLOOKUP(G12,PREMISAS!$B$44:$C$52,2,0) | AC12: =PREMISAS!C56 | AD12: =Q12+T12+V12+X12+AA12+AB12+AC12+IF(F12="C",I12*PREMISAS!C57,0)
A13: 10 | B13: T-MECA.A-04 | C13: Francisco Irazola | D13: IE4 | E13: Junín – Satipo | F13: C | G13: Mecánica Automotriz | H13: SI | I13: =IF(H13="SI",2,1) | J13: =PREMISAS!C11 | K13: =PREMISAS!C12 | L13: =PREMISAS!C9 | M13: =VLOOKUP(G13,PREMISAS!$B$16:$D$24,2,0) | N13: =VLOOKUP(G13,PREMISAS!$B$16:$D$24,3,0) | O13: =J13*L13*M13 | P13: =IF(H13="SI",K13*L13*N13,0) | Q13: =O13+P13 | R13: =VLOOKUP(F13,PREMISAS!$B$28:$F$30,3,0) | S13: =PREMISAS!C5+PREMISAS!C8 | T13: =R13*S13*I13 | U13: =VLOOKUP(F13,PREMISAS!$B$28:$F$30,4,0) | V13: =U13*PREMISAS!C5*I13 | W13: =VLOOKUP(D13,PREMISAS!$B$34:$F$40,5,0) | X13: =W13*I13 | Y13: =VLOOKUP(F13,PREMISAS!$B$28:$F$30,5,0) | Z13: =PREMISAS!C10 | AA13: =Y13*Z13*I13 | AB13: =VLOOKUP(G13,PREMISAS!$B$44:$C$52,2,0) | AC13: =PREMISAS!C56 | AD13: =Q13+T13+V13+X13+AA13+AB13+AC13+IF(F13="C",I13*PREMISAS!C57,0)
A14: 11 | B14: T-COMP-05 | C14: Guillermo E. Billinghurst | D14: IE5 | E14: Lima Provincia – Barranca | F14: B | G14: Computación e Informática | H14: NO | I14: =IF(H14="SI",2,1) | J14: =PREMISAS!C11 | K14: =PREMISAS!C12 | L14: =PREMISAS!C9 | M14: =VLOOKUP(G14,PREMISAS!$B$16:$D$24,2,0) | N14: =VLOOKUP(G14,PREMISAS!$B$16:$D$24,3,0) | O14: =J14*L14*M14 | P14: =IF(H14="SI",K14*L14*N14,0) | Q14: =O14+P14 | R14: =VLOOKUP(F14,PREMISAS!$B$28:$F$30,3,0) | S14: =PREMISAS!C5+PREMISAS!C8 | T14: =R14*S14*I14 | U14: =VLOOKUP(F14,PREMISAS!$B$28:$F$30,4,0) | V14: =U14*PREMISAS!C5*I14 | W14: =VLOOKUP(D14,PREMISAS!$B$34:$F$40,5,0) | X14: =W14*I14 | Y14: =VLOOKUP(F14,PREMISAS!$B$28:$F$30,5,0) | Z14: =PREMISAS!C10 | AA14: =Y14*Z14*I14 | AB14: =VLOOKUP(G14,PREMISAS!$B$44:$C$52,2,0) | AC14: =PREMISAS!C56 | AD14: =Q14+T14+V14+X14+AA14+AB14+AC14+IF(F14="C",I14*PREMISAS!C57,0)
A15: 12 | B15: T-EBAN-05 | C15: Guillermo E. Billinghurst | D15: IE5 | E15: Lima Provincia – Barranca | F15: B | G15: Ebanistería | H15: SI | I15: =IF(H15="SI",2,1) | J15: =PREMISAS!C11 | K15: =PREMISAS!C12 | L15: =PREMISAS!C9 | M15: =VLOOKUP(G15,PREMISAS!$B$16:$D$24,2,0) | N15: =VLOOKUP(G15,PREMISAS!$B$16:$D$24,3,0) | O15: =J15*L15*M15 | P15: =IF(H15="SI",K15*L15*N15,0) | Q15: =O15+P15 | R15: =VLOOKUP(F15,PREMISAS!$B$28:$F$30,3,0) | S15: =PREMISAS!C5+PREMISAS!C8 | T15: =R15*S15*I15 | U15: =VLOOKUP(F15,PREMISAS!$B$28:$F$30,4,0) | V15: =U15*PREMISAS!C5*I15 | W15: =VLOOKUP(D15,PREMISAS!$B$34:$F$40,5,0) | X15: =W15*I15 | Y15: =VLOOKUP(F15,PREMISAS!$B$28:$F$30,5,0) | Z15: =PREMISAS!C10 | AA15: =Y15*Z15*I15 | AB15: =VLOOKUP(G15,PREMISAS!$B$44:$C$52,2,0) | AC15: =PREMISAS!C56 | AD15: =Q15+T15+V15+X15+AA15+AB15+AC15+IF(F15="C",I15*PREMISAS!C57,0)
A16: 13 | B16: T-ELEC-05 | C16: Guillermo E. Billinghurst | D16: IE5 | E16: Lima Provincia – Barranca | F16: B | G16: Electricidad | H16: SI | I16: =IF(H16="SI",2,1) | J16: =PREMISAS!C11 | K16: =PREMISAS!C12 | L16: =PREMISAS!C9 | M16: =VLOOKUP(G16,PREMISAS!$B$16:$D$24,2,0) | N16: =VLOOKUP(G16,PREMISAS!$B$16:$D$24,3,0) | O16: =J16*L16*M16 | P16: =IF(H16="SI",K16*L16*N16,0) | Q16: =O16+P16 | R16: =VLOOKUP(F16,PREMISAS!$B$28:$F$30,3,0) | S16: =PREMISAS!C5+PREMISAS!C8 | T16: =R16*S16*I16 | U16: =VLOOKUP(F16,PREMISAS!$B$28:$F$30,4,0) | V16: =U16*PREMISAS!C5*I16 | W16: =VLOOKUP(D16,PREMISAS!$B$34:$F$40,5,0) | X16: =W16*I16 | Y16: =VLOOKUP(F16,PREMISAS!$B$28:$F$30,5,0) | Z16: =PREMISAS!C10 | AA16: =Y16*Z16*I16 | AB16: =VLOOKUP(G16,PREMISAS!$B$44:$C$52,2,0) | AC16: =PREMISAS!C56 | AD16: =Q16+T16+V16+X16+AA16+AB16+AC16+IF(F16="C",I16*PREMISAS!C57,0)
A17: 14 | B17: T-INDUS.A-05 | C17: Guillermo E. Billinghurst | D17: IE5 | E17: Lima Provincia – Barranca | F17: B | G17: Industria Alimentaria | H17: NO | I17: =IF(H17="SI",2,1) | J17: =PREMISAS!C11 | K17: =PREMISAS!C12 | L17: =PREMISAS!C9 | M17: =VLOOKUP(G17,PREMISAS!$B$16:$D$24,2,0) | N17: =VLOOKUP(G17,PREMISAS!$B$16:$D$24,3,0) | O17: =J17*L17*M17 | P17: =IF(H17="SI",K17*L17*N17,0) | Q17: =O17+P17 | R17: =VLOOKUP(F17,PREMISAS!$B$28:$F$30,3,0) | S17: =PREMISAS!C5+PREMISAS!C8 | T17: =R17*S17*I17 | U17: =VLOOKUP(F17,PREMISAS!$B$28:$F$30,4,0) | V17: =U17*PREMISAS!C5*I17 | W17: =VLOOKUP(D17,PREMISAS!$B$34:$F$40,5,0) | X17: =W17*I17 | Y17: =VLOOKUP(F17,PREMISAS!$B$28:$F$30,5,0) | Z17: =PREMISAS!C10 | AA17: =Y17*Z17*I17 | AB17: =VLOOKUP(G17,PREMISAS!$B$44:$C$52,2,0) | AC17: =PREMISAS!C56 | AD17: =Q17+T17+V17+X17+AA17+AB17+AC17+IF(F17="C",I17*PREMISAS!C57,0)
A18: 15 | B18: T-MECA.A-05 | C18: Guillermo E. Billinghurst | D18: IE5 | E18: Lima Provincia – Barranca | F18: B | G18: Mecánica Automotriz | H18: SI | I18: =IF(H18="SI",2,1) | J18: =PREMISAS!C11 | K18: =PREMISAS!C12 | L18: =PREMISAS!C9 | M18: =VLOOKUP(G18,PREMISAS!$B$16:$D$24,2,0) | N18: =VLOOKUP(G18,PREMISAS!$B$16:$D$24,3,0) | O18: =J18*L18*M18 | P18: =IF(H18="SI",K18*L18*N18,0) | Q18: =O18+P18 | R18: =VLOOKUP(F18,PREMISAS!$B$28:$F$30,3,0) | S18: =PREMISAS!C5+PREMISAS!C8 | T18: =R18*S18*I18 | U18: =VLOOKUP(F18,PREMISAS!$B$28:$F$30,4,0) | V18: =U18*PREMISAS!C5*I18 | W18: =VLOOKUP(D18,PREMISAS!$B$34:$F$40,5,0) | X18: =W18*I18 | Y18: =VLOOKUP(F18,PREMISAS!$B$28:$F$30,5,0) | Z18: =PREMISAS!C10 | AA18: =Y18*Z18*I18 | AB18: =VLOOKUP(G18,PREMISAS!$B$44:$C$52,2,0) | AC18: =PREMISAS!C56 | AD18: =Q18+T18+V18+X18+AA18+AB18+AC18+IF(F18="C",I18*PREMISAS!C57,0)
A19: 16 | B19: T-MECA.A-06 | C19: José Granda | D19: IE6 | E19: Lima Metropolitana – SMP | F19: A | G19: Mecánica Automotriz | H19: SI | I19: =IF(H19="SI",2,1) | J19: =PREMISAS!C11 | K19: =PREMISAS!C12 | L19: =PREMISAS!C9 | M19: =VLOOKUP(G19,PREMISAS!$B$16:$D$24,2,0) | N19: =VLOOKUP(G19,PREMISAS!$B$16:$D$24,3,0) | O19: =J19*L19*M19 | P19: =IF(H19="SI",K19*L19*N19,0) | Q19: =O19+P19 | R19: =VLOOKUP(F19,PREMISAS!$B$28:$F$30,3,0) | S19: =PREMISAS!C5+PREMISAS!C8 | T19: =R19*S19*I19 | U19: =VLOOKUP(F19,PREMISAS!$B$28:$F$30,4,0) | V19: =U19*PREMISAS!C5*I19 | W19: =VLOOKUP(D19,PREMISAS!$B$34:$F$40,5,0) | X19: =W19*I19 | Y19: =VLOOKUP(F19,PREMISAS!$B$28:$F$30,5,0) | Z19: =PREMISAS!C10 | AA19: =Y19*Z19*I19 | AB19: =VLOOKUP(G19,PREMISAS!$B$44:$C$52,2,0) | AC19: =PREMISAS!C56 | AD19: =Q19+T19+V19+X19+AA19+AB19+AC19+IF(F19="C",I19*PREMISAS!C57,0)
A20: 17 | B20: T-COMP-06 | C20: José Granda | D20: IE6 | E20: Lima Metropolitana – SMP | F20: A | G20: Computación e Informática | H20: NO | I20: =IF(H20="SI",2,1) | J20: =PREMISAS!C11 | K20: =PREMISAS!C12 | L20: =PREMISAS!C9 | M20: =VLOOKUP(G20,PREMISAS!$B$16:$D$24,2,0) | N20: =VLOOKUP(G20,PREMISAS!$B$16:$D$24,3,0) | O20: =J20*L20*M20 | P20: =IF(H20="SI",K20*L20*N20,0) | Q20: =O20+P20 | R20: =VLOOKUP(F20,PREMISAS!$B$28:$F$30,3,0) | S20: =PREMISAS!C5+PREMISAS!C8 | T20: =R20*S20*I20 | U20: =VLOOKUP(F20,PREMISAS!$B$28:$F$30,4,0) | V20: =U20*PREMISAS!C5*I20 | W20: =VLOOKUP(D20,PREMISAS!$B$34:$F$40,5,0) | X20: =W20*I20 | Y20: =VLOOKUP(F20,PREMISAS!$B$28:$F$30,5,0) | Z20: =PREMISAS!C10 | AA20: =Y20*Z20*I20 | AB20: =VLOOKUP(G20,PREMISAS!$B$44:$C$52,2,0) | AC20: =PREMISAS!C56 | AD20: =Q20+T20+V20+X20+AA20+AB20+AC20+IF(F20="C",I20*PREMISAS!C57,0)
A21: 18 | B21: T-INDUS.A-06 | C21: José Granda | D21: IE6 | E21: Lima Metropolitana – SMP | F21: A | G21: Industria Alimentaria | H21: NO | I21: =IF(H21="SI",2,1) | J21: =PREMISAS!C11 | K21: =PREMISAS!C12 | L21: =PREMISAS!C9 | M21: =VLOOKUP(G21,PREMISAS!$B$16:$D$24,2,0) | N21: =VLOOKUP(G21,PREMISAS!$B$16:$D$24,3,0) | O21: =J21*L21*M21 | P21: =IF(H21="SI",K21*L21*N21,0) | Q21: =O21+P21 | R21: =VLOOKUP(F21,PREMISAS!$B$28:$F$30,3,0) | S21: =PREMISAS!C5+PREMISAS!C8 | T21: =R21*S21*I21 | U21: =VLOOKUP(F21,PREMISAS!$B$28:$F$30,4,0) | V21: =U21*PREMISAS!C5*I21 | W21: =VLOOKUP(D21,PREMISAS!$B$34:$F$40,5,0) | X21: =W21*I21 | Y21: =VLOOKUP(F21,PREMISAS!$B$28:$F$30,5,0) | Z21: =PREMISAS!C10 | AA21: =Y21*Z21*I21 | AB21: =VLOOKUP(G21,PREMISAS!$B$44:$C$52,2,0) | AC21: =PREMISAS!C56 | AD21: =Q21+T21+V21+X21+AA21+AB21+AC21+IF(F21="C",I21*PREMISAS!C57,0)
A22: 19 | B22: T-INDUS.V-07 | C22: Manuel A. Mesones Muro | D22: IE7 | E22: San Martín – El Dorado | F22: C | G22: Industria del Vestido | H22: NO | I22: =IF(H22="SI",2,1) | J22: =PREMISAS!C11 | K22: =PREMISAS!C12 | L22: =PREMISAS!C9 | M22: =VLOOKUP(G22,PREMISAS!$B$16:$D$24,2,0) | N22: =VLOOKUP(G22,PREMISAS!$B$16:$D$24,3,0) | O22: =J22*L22*M22 | P22: =IF(H22="SI",K22*L22*N22,0) | Q22: =O22+P22 | R22: =VLOOKUP(F22,PREMISAS!$B$28:$F$30,3,0) | S22: =PREMISAS!C5+PREMISAS!C8 | T22: =R22*S22*I22 | U22: =VLOOKUP(F22,PREMISAS!$B$28:$F$30,4,0) | V22: =U22*PREMISAS!C5*I22 | W22: =VLOOKUP(D22,PREMISAS!$B$34:$F$40,5,0) | X22: =W22*I22 | Y22: =VLOOKUP(F22,PREMISAS!$B$28:$F$30,5,0) | Z22: =PREMISAS!C10 | AA22: =Y22*Z22*I22 | AB22: =VLOOKUP(G22,PREMISAS!$B$44:$C$52,2,0) | AC22: =PREMISAS!C56 | AD22: =Q22+T22+V22+X22+AA22+AB22+AC22+IF(F22="C",I22*PREMISAS!C57,0)
A23: 20 | B23: T-CONST.M-07 | C23: Manuel A. Mesones Muro | D23: IE7 | E23: San Martín – El Dorado | F23: C | G23: Construcciones Metálicas | H23: SI | I23: =IF(H23="SI",2,1) | J23: =PREMISAS!C11 | K23: =PREMISAS!C12 | L23: =PREMISAS!C9 | M23: =VLOOKUP(G23,PREMISAS!$B$16:$D$24,2,0) | N23: =VLOOKUP(G23,PREMISAS!$B$16:$D$24,3,0) | O23: =J23*L23*M23 | P23: =IF(H23="SI",K23*L23*N23,0) | Q23: =O23+P23 | R23: =VLOOKUP(F23,PREMISAS!$B$28:$F$30,3,0) | S23: =PREMISAS!C5+PREMISAS!C8 | T23: =R23*S23*I23 | U23: =VLOOKUP(F23,PREMISAS!$B$28:$F$30,4,0) | V23: =U23*PREMISAS!C5*I23 | W23: =VLOOKUP(D23,PREMISAS!$B$34:$F$40,5,0) | X23: =W23*I23 | Y23: =VLOOKUP(F23,PREMISAS!$B$28:$F$30,5,0) | Z23: =PREMISAS!C10 | AA23: =Y23*Z23*I23 | AB23: =VLOOKUP(G23,PREMISAS!$B$44:$C$52,2,0) | AC23: =PREMISAS!C56 | AD23: =Q23+T23+V23+X23+AA23+AB23+AC23+IF(F23="C",I23*PREMISAS!C57,0)
A24: 21 | B24: T-EBAN-07 | C24: Manuel A. Mesones Muro | D24: IE7 | E24: San Martín – El Dorado | F24: C | G24: Ebanistería | H24: SI | I24: =IF(H24="SI",2,1) | J24: =PREMISAS!C11 | K24: =PREMISAS!C12 | L24: =PREMISAS!C9 | M24: =VLOOKUP(G24,PREMISAS!$B$16:$D$24,2,0) | N24: =VLOOKUP(G24,PREMISAS!$B$16:$D$24,3,0) | O24: =J24*L24*M24 | P24: =IF(H24="SI",K24*L24*N24,0) | Q24: =O24+P24 | R24: =VLOOKUP(F24,PREMISAS!$B$28:$F$30,3,0) | S24: =PREMISAS!C5+PREMISAS!C8 | T24: =R24*S24*I24 | U24: =VLOOKUP(F24,PREMISAS!$B$28:$F$30,4,0) | V24: =U24*PREMISAS!C5*I24 | W24: =VLOOKUP(D24,PREMISAS!$B$34:$F$40,5,0) | X24: =W24*I24 | Y24: =VLOOKUP(F24,PREMISAS!$B$28:$F$30,5,0) | Z24: =PREMISAS!C10 | AA24: =Y24*Z24*I24 | AB24: =VLOOKUP(G24,PREMISAS!$B$44:$C$52,2,0) | AC24: =PREMISAS!C56 | AD24: =Q24+T24+V24+X24+AA24+AB24+AC24+IF(F24="C",I24*PREMISAS!C57,0)
A25: TOTAL | I25: =SUM(I4:I24) | J25: =SUM(J4:J24) | K25: =SUM(K4:K24) | L25: =SUM(L4:L24) | M25: =SUM(M4:M24) | N25: =SUM(N4:N24) | O25: =SUM(O4:O24) | P25: =SUM(P4:P24) | ... AD25: =SUM(AD4:AD24)

Sheet RESUMEN IE
B1: RESUMEN DE COSTOS POR IE
B3: RESUMEN POR INSTITUCIÓN EDUCATIVA
B4: IE Código | C4: IE Nombre | D4: Grupo | E4: TOTAL S/.
B5: IE1 | C5: 16449 Eloy Soberón Flores | D5: C | E5: =SUMIF('DETALLE M4'!$D$4:$D$24,B5,'DETALLE M4'!$AD$4:$AD$24)
B6: IE2 | C6: 2026 Simón Bolívar | D6: A | E6: =SUMIF('DETALLE M4'!$D$4:$D$24,B6,'DETALLE M4'!$AD$4:$AD$24)
B7: IE3 | C7: 6049 Ricardo Palma | D7: A | E7: =SUMIF('DETALLE M4'!$D$4:$D$24,B7,'DETALLE M4'!$AD$4:$AD$24)
B8: IE4 | C8: Francisco Irazola | D8: C | E8: =SUMIF('DETALLE M4'!$D$4:$D$24,B8,'DETALLE M4'!$AD$4:$AD$24)
B9: IE5 | C9: Guillermo E. Billinghurst | D9: B | E9: =SUMIF('DETALLE M4'!$D$4:$D$24,B9,'DETALLE M4'!$AD$4:$AD$24)
B10: IE6 | C10: José Granda | D10: A | E10: =SUMIF('DETALLE M4'!$D$4:$D$24,B10,'DETALLE M4'!$AD$4:$AD$24)
B11: IE7 | C11: Manuel A. Mesones Muro | D11: C | E11: =SUMIF('DETALLE M4'!$D$4:$D$24,B11,'DETALLE M4'!$AD$4:$AD$24)
B12: TOTAL | E12: =SUM(E5:E11)

Sheet RESUMEN ESPECIALIDAD
B1: RESUMEN DE COSTOS POR ESPECIALIDAD
B3: RESUMEN POR ESPECIALIDAD
B4: Especialidad | C4: # Talleres | D4: TOTAL S/.
B5: Cocina y Repostería | C5: 1 | D5: =SUMIF('DETALLE M4'!$G$4:$G$24,B5,'DETALLE M4'!$AD$4:$AD$24)
B6: Computación e Informática | C6: 4 | D6: =SUMIF('DETALLE M4'!$G$4:$G$24,B6,'DETALLE M4'!$AD$4:$AD$24)
B7: Construcciones Metálicas | C7: 1 | D7: =SUMIF('DETALLE M4'!$G$4:$G$24,B7,'DETALLE M4'!$AD$4:$AD$24)
B8: Ebanistería | C8: 2 | D8: =SUMIF('DETALLE M4'!$G$4:$G$24,B8,'DETALLE M4'!$AD$4:$AD$24)
B9: Electricidad | C9: 3 | D9: =SUMIF('DETALLE M4'!$G$4:$G$24,B9,'DETALLE M4'!$AD$4:$AD$24)
B10: Electrónica | C10: 1 | D10: =SUMIF('DETALLE M4'!$G$4:$G$24,B10,'DETALLE M4'!$AD$4:$AD$24)
B11: Industria Alimentaria | C11: 4 | D11: =SUMIF('DETALLE M4'!$G$4:$G$24,B11,'DETALLE M4'!$AD$4:$AD$24)
B12: Industria del Vestido | C12: 2 | D12: =SUMIF('DETALLE M4'!$G$4:$G$24,B12,'DETALLE M4'!$AD$4:$AD$24)
B13: Mecánica Automotriz | C13: 3 | D13: =SUMIF('DETALLE M4'!$G$4:$G$24,B13,'DETALLE M4'!$AD$4:$AD$24)
B14: TOTAL | C14: =SUM(C5:C13) | D14: =SUM(D5:D13)
